<?xml version="1.0" encoding="utf-8"?>
<!-- =================================================================================== -->
<!-- |    This document was autogenerated by xacro from robot2_xacro.xacro             | -->
<!-- |    EDITING THIS FILE BY HAND IS NOT RECOMMENDED                                 | -->
<!-- =================================================================================== -->
<robot name="robot2_xacro" xmlns:controller="http://playerstage.sourceforge.net/gazebo/xmlschema/#controller" xmlns:interface="http://playerstage.sourceforge.net/gazebo/xmlschema/#interface" xmlns:sensor="http://playerstage.sourceforge.net/gazebo/xmlschema/#sensor" xmlns:xacro="http://www.ros.org/wiki/xacro">
  <link name="base_footprint">
    <inertial>
      <mass value="0.0001"/>
      <origin xyz="0 0 0"/>
      <inertia ixx="1.0" ixy="0.0" ixz="0.0" iyy="1.0" iyz="0.0" izz="1.0"/>
    </inertial>
    <visual>
      <origin rpy="0 0 0" xyz="0 0 0"/>
      <geometry>
        <box size="0.001 0.001 0.001"/>
      </geometry>
    </visual>
  </link>
  <joint name="base_footprint_baselink" type="fixed">
    <origin xyz="0 0 0"/>
    <parent link="base_footprint"/>
    <child link="base_link"/>
  </joint>
  <link name="wheel_support1">
    <visual>
      <geometry>
        <box size="0.6 0.05 0.2"/>
      </geometry>
      <material name="white">
        <color rgba="1 1 1 1"/>
      </material>
    </visual>
    <collision>
      <geometry>
        <box size="0.6 0.05 0.2"/>
      </geometry>
    </collision>
    <inertial>
      <mass value="10"/>
      <inertia ixx="1.0" ixy="0.0" ixz="0.0" iyy="1.0" iyz="0.0" izz="1.0"/>
    </inertial>
  </link>
  <joint name="base_to_wheel_support1" type="fixed">
    <parent link="base_link"/>
    <child link="wheel_support1"/>
    <origin rpy="0 0 0" xyz="0 -0.2 0.375"/>
  </joint>
  <link name="wheel_support2">
    <visual>
      <geometry>
        <box size="0.6 0.05 0.2"/>
      </geometry>
      <material name="white">
        <color rgba="1 1 1 1"/>
      </material>
    </visual>
    <collision>
      <geometry>
        <box size="0.6 0.05 0.2"/>
      </geometry>
    </collision>
    <inertial>
      <mass value="10"/>
      <inertia ixx="1.0" ixy="0.0" ixz="0.0" iyy="1.0" iyz="0.0" izz="1.0"/>
    </inertial>
  </link>
  <joint name="base_to_wheel_support2" type="fixed">
    <parent link="base_link"/>
    <child link="wheel_support2"/>
    <origin rpy="0 0 0" xyz="0 0.2 0.375"/>
  </joint>
  <link name="wheel_support3">
    <visual>
      <geometry>
        <box size="0.3 0.05 0.1"/>
      </geometry>
      <material name="white"/>
    </visual>
    <collision>
      <geometry>
        <box size="0.3 0.05 0.1"/>
      </geometry>
    </collision>
    <inertial>
      <mass value="10"/>
      <inertia ixx="1.0" ixy="0.0" ixz="0.0" iyy="1.0" iyz="0.0" izz="1.0"/>
    </inertial>
  </link>
  <joint name="wheel_support1_to_wheel_support3" type="fixed">
    <parent link="wheel_support1"/>
    <child link="wheel_support3"/>
    <origin rpy="0 0 0" xyz="0.2 0 -0.15"/>
  </joint>
  <link name="wheel_support4">
    <visual>
      <geometry>
        <box size="0.3 0.05 0.1"/>
      </geometry>
      <material name="white"/>
    </visual>
    <collision>
      <geometry>
        <box size="0.3 0.05 0.1"/>
      </geometry>
    </collision>
    <inertial>
      <mass value="10"/>
      <inertia ixx="1.0" ixy="0.0" ixz="0.0" iyy="1.0" iyz="0.0" izz="1.0"/>
    </inertial>
  </link>
  <joint name="wheel_support2_to_wheel_support4" type="fixed">
    <parent link="wheel_support2"/>
    <child link="wheel_support4"/>
    <origin rpy="0 0 0" xyz="0.2 0 -0.15"/>
  </joint>
  <link name="base_link">
    <visual>
      <geometry>
        <box size="0.43 0.45 0.05"/>
      </geometry>
      <origin rpy="0 0 0" xyz="0 0 0.5"/>
      <material name="grey">
        <color rgba="0.82745 0.82745 0.82745 1"/>
      </material>
    </visual>
    <collision>
      <geometry>
        <box size="0.43 0.45 0.05"/>
      </geometry>
    </collision>
    <inertial>
      <mass value="10"/>
      <inertia ixx="1.0" ixy="0.0" ixz="0.0" iyy="1.0" iyz="0.0" izz="1.0"/>
    </inertial>
  </link>
  <link name="wheel_1">
    <visual>
      <geometry>
        <cylinder length="0.064" radius="0.2032"/>
      </geometry>
      <material name="black">
        <color rgba="0 0 0 1"/>
      </material>
    </visual>
    <collision>
      <geometry>
        <cylinder length="0.064" radius="0.2032"/>
      </geometry>
    </collision>
    <inertial>
      <mass value="10"/>
      <inertia ixx="1.0" ixy="0.0" ixz="0.0" iyy="1.0" iyz="0.0" izz="1.0"/>
    </inertial>
  </link>
  <joint name="wheel_support3_to_wheel_1" type="continuous">
    <parent link="wheel_support3"/>
    <child link="wheel_1"/>
    <origin rpy="1.5707 0 0" xyz="0.08 -0.057 -0.0468"/>
    <axis xyz="0 0 1"/>
  </joint>
  <link name="wheel_2">
    <visual>
      <geometry>
        <cylinder length="0.064" radius="0.2032"/>
      </geometry>
      <material name="black">
        <color rgba="0 0 0 1"/>
      </material>
    </visual>
    <collision>
      <geometry>
        <cylinder length="0.064" radius="0.2032"/>
      </geometry>
    </collision>
    <inertial>
      <mass value="10"/>
      <inertia ixx="1.0" ixy="0.0" ixz="0.0" iyy="1.0" iyz="0.0" izz="1.0"/>
    </inertial>
  </link>
  <joint name="wheel_support4_to_wheel_2" type="continuous">
    <parent link="wheel_support4"/>
    <child link="wheel_2"/>
    <origin rpy="1.5707 0 0" xyz="0.08 0.057 -0.0468"/>
    <axis xyz="0 0 1"/>
  </joint>
  <transmission name="wheel1_swivel_trans">
    <type>transmission_interface/SimpleTransmission</type>
    <actuator name="wheel1_swivel_motor">
      <mechanicalReduction>1</mechanicalReduction>
    </actuator>
    <joint name="wheel_support3_to_wheel_1">
      <hardwareInterface>PositionJointInterface</hardwareInterface>
    </joint>
  </transmission>
  <transmission name="wheel2_swivel_trans">
    <type>transmission_interface/SimpleTransmission</type>
    <actuator name="wheel2_swivel_motor">
      <mechanicalReduction>1</mechanicalReduction>
    </actuator>
    <joint name="wheel_support4_to_wheel_2">
      <hardwareInterface>PositionJointInterface</hardwareInterface>
    </joint>
  </transmission>
  <gazebo reference="suffix_wheel">
    <mu1 value="200.0"/>
    <mu2 value="100.0"/>
    <kp value="10000000.0"/>
    <kd value="1.0"/>
    <material>Gazebo/Grey</material>
  </gazebo>
  <link name="wheel_3">
    <visual>
      <geometry>
        <cylinder length="0.052" radius="0.127"/>
      </geometry>
      <material name="black"/>
    </visual>
    <collision>
      <geometry>
        <cylinder length="0.052" radius="0.127"/>
      </geometry>
    </collision>
    <inertial>
      <mass value="10"/>
      <inertia ixx="1.0" ixy="0.0" ixz="0.0" iyy="1.0" iyz="0.0" izz="1.0"/>
    </inertial>
  </link>
  <link name="wheel_4">
    <visual>
      <geometry>
        <cylinder length="0.052" radius="0.127"/>
      </geometry>
      <material name="black"/>
    </visual>
    <collision>
      <geometry>
        <cylinder length="0.052" radius="0.127"/>
      </geometry>
    </collision>
    <inertial>
      <mass value="10"/>
      <inertia ixx="1.0" ixy="0.0" ixz="0.0" iyy="1.0" iyz="0.0" izz="1.0"/>
    </inertial>
  </link>
  <link name="backrest">
    <visual>
      <geometry>
        <box size="0.01 0.4 0.35"/>
      </geometry>
      <material name="white"/>
    </visual>
    <collision>
      <geometry>
        <box size="0.01 0.4 0.35"/>
      </geometry>
    </collision>
    <inertial>
      <mass value="10"/>
      <inertia ixx="1.0" ixy="0.0" ixz="0.0" iyy="1.0" iyz="0.0" izz="1.0"/>
    </inertial>
  </link>
  <joint name="base_to_back" type="fixed">
    <parent link="base_link"/>
    <child link="backrest"/>
    <origin rpy="0 0 0" xyz="0.215 0 0.72"/>
  </joint>
  <link name="backsupport1">
    <visual>
      <geometry>
        <cylinder length="0.44" radius="0.015"/>
      </geometry>
      <material name="white"/>
    </visual>
    <collision>
      <geometry>
        <cylinder length="0.44" radius="0.015"/>
      </geometry>
    </collision>
    <inertial>
      <mass value="10"/>
      <inertia ixx="1.0" ixy="0.0" ixz="0.0" iyy="1.0" iyz="0.0" izz="1.0"/>
    </inertial>
  </link>
  <link name="hand1">
    <visual>
      <geometry>
        <cylinder length="0.06" radius="0.015"/>
      </geometry>
      <material name="white"/>
    </visual>
    <collision>
      <geometry>
        <cylinder length="0.06" radius="0.015"/>
      </geometry>
    </collision>
    <inertial>
      <mass value="10"/>
      <inertia ixx="1.0" ixy="0.0" ixz="0.0" iyy="1.0" iyz="0.0" izz="1.0"/>
    </inertial>
  </link>
  <joint name="base_to_backsupport1" type="fixed">
    <parent link="base_link"/>
    <child link="backsupport1"/>
    <origin rpy="0 0 0" xyz="0.215 -0.2 0.72"/>
  </joint>
  <joint name="backsupport1_to_hand1" type="fixed">
    <parent link="backsupport1"/>
    <child link="hand1"/>
    <origin rpy="0 1.5707 0" xyz="0.03 0 0.22"/>
  </joint>
  <link name="backsupport2">
    <visual>
      <geometry>
        <cylinder length="0.44" radius="0.015"/>
      </geometry>
      <material name="white"/>
    </visual>
    <collision>
      <geometry>
        <cylinder length="0.44" radius="0.015"/>
      </geometry>
    </collision>
    <inertial>
      <mass value="10"/>
      <inertia ixx="1.0" ixy="0.0" ixz="0.0" iyy="1.0" iyz="0.0" izz="1.0"/>
    </inertial>
  </link>
  <link name="hand2">
    <visual>
      <geometry>
        <cylinder length="0.06" radius="0.015"/>
      </geometry>
      <material name="white"/>
    </visual>
    <collision>
      <geometry>
        <cylinder length="0.06" radius="0.015"/>
      </geometry>
    </collision>
    <inertial>
      <mass value="10"/>
      <inertia ixx="1.0" ixy="0.0" ixz="0.0" iyy="1.0" iyz="0.0" izz="1.0"/>
    </inertial>
  </link>
  <joint name="base_to_backsupport2" type="fixed">
    <parent link="base_link"/>
    <child link="backsupport2"/>
    <origin rpy="0 0 0" xyz="0.215 0.2 0.72"/>
  </joint>
  <joint name="backsupport2_to_hand2" type="fixed">
    <parent link="backsupport2"/>
    <child link="hand2"/>
    <origin rpy="0 1.5707 0" xyz="0.03 0 0.22"/>
  </joint>
  <link name="arm1">
    <visual>
      <geometry>
        <cylinder length="0.4" radius="0.015"/>
      </geometry>
      <material name="white"/>
    </visual>
    <collision>
      <geometry>
        <cylinder length="0.4" radius="0.015"/>
      </geometry>
    </collision>
    <inertial>
      <mass value="10"/>
      <inertia ixx="1.0" ixy="0.0" ixz="0.0" iyy="1.0" iyz="0.0" izz="1.0"/>
    </inertial>
  </link>
  <link name="armsupport1">
    <visual>
      <geometry>
        <cylinder length="0.3" radius="0.015"/>
      </geometry>
      <material name="white"/>
    </visual>
    <collision>
      <geometry>
        <cylinder length="0.3" radius="0.015"/>
      </geometry>
    </collision>
    <inertial>
      <mass value="10"/>
      <inertia ixx="1.0" ixy="0.0" ixz="0.0" iyy="1.0" iyz="0.0" izz="1.0"/>
    </inertial>
  </link>
  <joint name="base_to_armsupport1" type="fixed">
    <parent link="base_link"/>
    <child link="armsupport1"/>
    <origin rpy="0 0 0" xyz="-0.1 -0.2 0.65"/>
  </joint>
  <joint name="armsupport1_to_arm1" type="fixed">
    <parent link="armsupport1"/>
    <child link="arm1"/>
    <origin rpy="0 1.5707 0" xyz="0.12 0 0.15"/>
  </joint>
  <link name="arm2">
    <visual>
      <geometry>
        <cylinder length="0.4" radius="0.015"/>
      </geometry>
      <material name="white"/>
    </visual>
    <collision>
      <geometry>
        <cylinder length="0.4" radius="0.015"/>
      </geometry>
    </collision>
    <inertial>
      <mass value="10"/>
      <inertia ixx="1.0" ixy="0.0" ixz="0.0" iyy="1.0" iyz="0.0" izz="1.0"/>
    </inertial>
  </link>
  <link name="armsupport2">
    <visual>
      <geometry>
        <cylinder length="0.3" radius="0.015"/>
      </geometry>
      <material name="white"/>
    </visual>
    <collision>
      <geometry>
        <cylinder length="0.3" radius="0.015"/>
      </geometry>
    </collision>
    <inertial>
      <mass value="10"/>
      <inertia ixx="1.0" ixy="0.0" ixz="0.0" iyy="1.0" iyz="0.0" izz="1.0"/>
    </inertial>
  </link>
  <joint name="base_to_armsupport2" type="fixed">
    <parent link="base_link"/>
    <child link="armsupport2"/>
    <origin rpy="0 0 0" xyz="-0.1 0.2 0.65"/>
  </joint>
  <joint name="armsupport2_to_arm2" type="fixed">
    <parent link="armsupport2"/>
    <child link="arm2"/>
    <origin rpy="0 1.5707 0" xyz="0.12 0 0.15"/>
  </joint>
  <link name="spiale_1">
    <visual>
      <geometry>
        <cylinder length="0.11" radius="0.015"/>
      </geometry>
      <material name="white"/>
    </visual>
    <collision>
      <geometry>
        <cylinder length="0.11" radius="0.015"/>
      </geometry>
    </collision>
    <inertial>
      <mass value="10"/>
      <inertia ixx="1.0" ixy="0.0" ixz="0.0" iyy="1.0" iyz="0.0" izz="1.0"/>
    </inertial>
  </link>
  <link name="spiale_4">
    <visual>
      <geometry>
        <cylinder length="0.138" radius="0.015"/>
      </geometry>
      <material name="white"/>
    </visual>
    <collision>
      <geometry>
        <cylinder length="0.138" radius="0.015"/>
      </geometry>
    </collision>
    <inertial>
      <mass value="10"/>
      <inertia ixx="1.0" ixy="0.0" ixz="0.0" iyy="1.0" iyz="0.0" izz="1.0"/>
    </inertial>
  </link>
  <joint name="base_to_spiale_1" type="fixed">
    <parent link="base_link"/>
    <child link="spiale_1"/>
    <origin rpy="0 0 0" xyz="-0.28 -0.24 0.32"/>
  </joint>
  <joint name="spiale_1_to_spiale_4" type="continuous">
    <parent link="spiale_1"/>
    <child link="spiale_4"/>
    <origin rpy="0 0.07 0" xyz="-0.005 0 -0.124"/>
    <axis xyz="0 0 1"/>
  </joint>
  <joint name="spiale_4_to_wheel_4" type="continuous">
    <parent link="spiale_4"/>
    <child link="wheel_4"/>
    <origin rpy="1.5707 0 0" xyz="-0.005 0 -0.069"/>
    <axis xyz="0 0 1"/>
  </joint>
  <link name="spiale_2">
    <visual>
      <geometry>
        <cylinder length="0.11" radius="0.015"/>
      </geometry>
      <material name="white"/>
    </visual>
    <collision>
      <geometry>
        <cylinder length="0.11" radius="0.015"/>
      </geometry>
    </collision>
    <inertial>
      <mass value="10"/>
      <inertia ixx="1.0" ixy="0.0" ixz="0.0" iyy="1.0" iyz="0.0" izz="1.0"/>
    </inertial>
  </link>
  <link name="spiale_3">
    <visual>
      <geometry>
        <cylinder length="0.138" radius="0.015"/>
      </geometry>
      <material name="white"/>
    </visual>
    <collision>
      <geometry>
        <cylinder length="0.138" radius="0.015"/>
      </geometry>
    </collision>
    <inertial>
      <mass value="10"/>
      <inertia ixx="1.0" ixy="0.0" ixz="0.0" iyy="1.0" iyz="0.0" izz="1.0"/>
    </inertial>
  </link>
  <joint name="base_to_spiale_2" type="fixed">
    <parent link="base_link"/>
    <child link="spiale_2"/>
    <origin rpy="0 0 0" xyz="-0.28 0.24 0.32"/>
  </joint>
  <joint name="spiale_2_to_spiale_3" type="continuous">
    <parent link="spiale_2"/>
    <child link="spiale_3"/>
    <origin rpy="0 0.07 0" xyz="-0.005 0 -0.124"/>
    <axis xyz="0 0 1"/>
  </joint>
  <joint name="spiale_3_to_wheel_3" type="continuous">
    <parent link="spiale_3"/>
    <child link="wheel_3"/>
    <origin rpy="1.5707 0 0" xyz="-0.005 0 -0.069"/>
    <axis xyz="0 0 1"/>
  </joint>
  <link name="hokuyo_link">
    <visual>
      <geometry>
        <box size="0.1 0.1 0.05"/>
      </geometry>
      <material name="white"/>
    </visual>
    <collision>
      <geometry>
        <box size="0.1 0.1 0.05"/>
      </geometry>
    </collision>
    <inertial>
      <mass value="10"/>
      <inertia ixx="1.0" ixy="0.0" ixz="0.0" iyy="1.0" iyz="0.0" izz="1.0"/>
    </inertial>
  </link>
  <joint name="base_to_hokuyo" type="fixed">
    <parent link="base_link"/>
    <child link="hokuyo_link"/>
    <origin rpy="0 0 0" xyz="-0.1 0 0.55"/>
  </joint>
  <gazebo reference="hokuyo_link">
    <sensor name="head_hokuyo_sensor" type="ray">
      <pose>0 0 0 0 0 0</pose>
      <visualize>true</visualize>
      <update_rate>40</update_rate>
      <ray>
        <scan>
          <horizontal>
            <samples>720</samples>
            <resolution>1</resolution>
            <min_angle>-1.570796</min_angle>
            <max_angle>1.570796</max_angle>
          </horizontal>
        </scan>
        <range>
          <min>0.10</min>
          <max>30.0</max>
          <resolution>0.01</resolution>
        </range>
        <noise>
          <type>gaussian</type>
          <mean>0.0</mean>
          <stddev>0.01</stddev>
        </noise>
      </ray>
      <plugin filename="libgazebo_ros_laser.so" name="gazebo_ros_head_hokuyo_controller">
        <topicName>/rrbot/laser/scan</topicName>
        <frameName>hokuyo_link</frameName>
      </plugin>
    </sensor>
  </gazebo>
  <gazebo>
    <plugin filename="libgazebo_ros_diff_drive.so" name="differential_drive_controller">
      <rosDebugLevel>Debug</rosDebugLevel>
      <publishWheelTF>true</publishWheelTF>
      <robotNamespace>/</robotNamespace>
      <publishTf>1</publishTf>
      <publishWheelJointState>true</publishWheelJointState>
      <alwaysOn>true</alwaysOn>
      <updateRate>100.0</updateRate>
      <legacyMode>true</legacyMode>
      <leftJoint>wheel_support3_to_wheel_1</leftJoint>
      <rightJoint>wheel_support4_to_wheel_2</rightJoint>
      <wheelSeparation>0.114</wheelSeparation>
      <wheelDiameter>0.4064</wheelDiameter>
      <broadcastTF>1</broadcastTF>
      <wheelTorque>20</wheelTorque>
      <wheelAcceleration>1.8</wheelAcceleration>
      <commandTopic>cmd_vel</commandTopic>
      <odometryTopic>odom</odometryTopic>
      <odometryFrame>odom</odometryFrame>
      <robotBaseFrame>base_footprint</robotBaseFrame>
    </plugin>
  </gazebo>
  <gazebo>
    <plugin filename="libgazebo_ros_control.so" name="gazebo_ros_control">
      <robotNamespace>/</robotNamespace>
    </plugin>
  </gazebo>
</robot>

